Traceback (most recent call last):
  File "C:\Users\User\anaconda3\lib\site-packages\jupyter_cache\executors\utils.py", line 51, in single_nb_execution
    executenb(
  File "C:\Users\User\anaconda3\lib\site-packages\nbclient\client.py", line 1204, in execute
    return NotebookClient(nb=nb, resources=resources, km=km, **kwargs).execute()
  File "C:\Users\User\anaconda3\lib\site-packages\nbclient\util.py", line 84, in wrapped
    return just_run(coro(*args, **kwargs))
  File "C:\Users\User\anaconda3\lib\site-packages\nbclient\util.py", line 62, in just_run
    return loop.run_until_complete(coro)
  File "C:\Users\User\anaconda3\lib\asyncio\base_events.py", line 616, in run_until_complete
    return future.result()
  File "C:\Users\User\anaconda3\lib\site-packages\nbclient\client.py", line 663, in async_execute
    await self.async_execute_cell(
  File "C:\Users\User\anaconda3\lib\site-packages\nbclient\client.py", line 965, in async_execute_cell
    await self._check_raise_for_error(cell, cell_index, exec_reply)
  File "C:\Users\User\anaconda3\lib\site-packages\nbclient\client.py", line 862, in _check_raise_for_error
    raise CellExecutionError.from_cell_and_msg(cell, exec_reply_content)
nbclient.exceptions.CellExecutionError: An error occurred while executing the following cell:
------------------
# Tab complete to check out all the read functions available
pd.read_
------------------

[1;31m---------------------------------------------------------------------------[0m
[1;31mAttributeError[0m                            Traceback (most recent call last)
Input [1;32mIn [5][0m, in [0;36m<cell line: 2>[1;34m()[0m
[0;32m      1[0m [38;5;66;03m# Tab complete to check out all the read functions available[39;00m
[1;32m----> 2[0m [43mpd[49m[38;5;241;43m.[39;49m[43mread_[49m

File [1;32m~\anaconda3\lib\site-packages\pandas\__init__.py:261[0m, in [0;36m__getattr__[1;34m(name)[0m
[0;32m    257[0m     [38;5;28;01mfrom[39;00m [38;5;21;01mpandas[39;00m[38;5;21;01m.[39;00m[38;5;21;01mcore[39;00m[38;5;21;01m.[39;00m[38;5;21;01marrays[39;00m[38;5;21;01m.[39;00m[38;5;21;01msparse[39;00m [38;5;28;01mimport[39;00m SparseArray [38;5;28;01mas[39;00m _SparseArray
[0;32m    259[0m     [38;5;28;01mreturn[39;00m _SparseArray
[1;32m--> 261[0m [38;5;28;01mraise[39;00m [38;5;167;01mAttributeError[39;00m([38;5;124mf[39m[38;5;124m"[39m[38;5;124mmodule [39m[38;5;124m'[39m[38;5;124mpandas[39m[38;5;124m'[39m[38;5;124m has no attribute [39m[38;5;124m'[39m[38;5;132;01m{[39;00mname[38;5;132;01m}[39;00m[38;5;124m'[39m[38;5;124m"[39m)

[1;31mAttributeError[0m: module 'pandas' has no attribute 'read_'
AttributeError: module 'pandas' has no attribute 'read_'

